<?xml version="1.0"?>
<robot name="echelon">
    <material name="white">
        <color rgba="1 1 1 1"/>
    </material>

    <material name="black">
        <color rgba="0.3 0.3 0.3 1"/>
    </material>

    <material name="orange">
        <color rgba="0 0.8 1 1"/>
    </material>

    <material name="blue">
        <color rgba="0.0 0.0 1.0 1.0" />
    </material>

    <link name="world">
        <visual>
            <geometry>
                <box size="1 0.5 0.1" />
            </geometry>
            <origin xyz="0 0 -0.05" rpy="0 0 0" />
            <material name="white"/>
        </visual>
    </link>

    <link name="base_link">
        <visual>
            <geometry>
                <mesh filename="package://robot_description/meshes/Base_link.stl" scale="0.001 0.001 0.001"/>
            </geometry>
            <origin xyz="0 0 0" rpy="0 0 0" />
            <material name="black"/>
        </visual>
    </link>

    <joint name="world_base_joint" type="continuous">
        <parent link="world"/>
        <child link="base_link"/>
        <origin xyz="0 0 0" rpy="0 0 -1.5708"/>
        <axis xyz="0 0 1"/>
    </joint>

    <link name="shoulder_link">
        <visual>
            <geometry>
                <mesh filename="package://robot_description/meshes/Shoulder_link.stl" scale="0.001 0.001 0.001"/>
            </geometry>
            <origin xyz="0 0 0" rpy="0 1.5708 0"/>
            <material name="orange"/>
        </visual>
    </link>

    <joint name="base_shoulder_joint" type="continuous">
         <parent link="base_link" />
         <child link="shoulder_link" />
         <origin xyz="-0.0635 0 0.227" rpy="0 0 0" />
         <axis xyz="1 0 0"/>
    </joint>

    <link name="elbow_link">
        <visual>
            <geometry>
                <mesh filename="package://robot_description/meshes/Elbow_link.stl" scale="0.001 0.001 0.001"/>
            </geometry>
            <origin xyz="0 0 0" rpy="0 1.5708 0"/>
            <material name="orange"/>
        </visual>
    </link>

    <joint name="shoulder_elbow_joint" type="continuous">
        <parent link="shoulder_link" />
        <child link="elbow_link" />
        <origin xyz="0 0.381 0" rpy="0 0 0" />
        <axis xyz="1 0 0"/>
    </joint>

    <link name="wrist_main_link">
        <visual>
            <geometry>
                <mesh filename="package://robot_description/meshes/Wrist_main_link.stl" scale="0.001 0.001 0.001"/>
            </geometry>
            <origin xyz="0 -0.05715 -0.05715" rpy="0 0 0"/>
            <material name="orange"/>
        </visual>
    </link>

    <joint name="elbow_wrist_main_joint" type="continuous">
        <parent link="elbow_link" />
        <child link="wrist_main_link" />
        <origin xyz="0.05715 0.1524 0" rpy="-1.5708 0 1.5708" />
        <axis xyz="1 0 0"/>
    </joint>

    <link name="wrist_secondary_link">
        <visual>
            <geometry>
                <mesh filename="package://robot_description/meshes/Wrist_secondary_link.stl" scale="0.001 0.001 0.001"/>
            </geometry>
            <origin xyz="0 0 -0.04445" rpy="0 0 0"/>
            <material name="orange"/>
        </visual>
    </link>

    <joint name="wrist_main_wrist_secondary_joint" type="continuous">
        <parent link="wrist_main_link" />
        <child link="wrist_secondary_link" />
        <origin xyz="0.2286 0 0" rpy="0 0 1.5708" />
        <axis xyz="0 0 1"/>
    </joint>

    <link name="wrist_tertiary_link">
        <visual>
            <geometry>
                <mesh filename="package://robot_description/meshes/Wrist_tertiary_link.stl" scale="0.001 0.001 0.001"/>
            </geometry>
            <origin xyz="0 0 -0.0254" rpy="0 0 0"/>
            <material name="blue"/>
        </visual>
    </link>

    <joint name="wrist_secondary_wrist_tertiary_joint" type="continuous">
        <parent link="wrist_secondary_link" />
        <child link="wrist_tertiary_link" />
        <origin xyz="0 -0.08001 0" rpy="1.5708 0 0" />
        <axis xyz="0 0 1"/>
    </joint>
</robot>
